2020-06-30 08:06:08,281 WARNING file_cache is unavailable when using oauth2client >= 4.0.0 or google-auth @ autodetect from module __init__
Traceback (most recent call last):
  File "/home/tecimler96/APP/venv/lib/python3.8/site-packages/googleapiclient/discovery_cache/file_cache.py", line 33, in <module>
    from oauth2client.contrib.locked_file import LockedFile
ModuleNotFoundError: No module named 'oauth2client'

During handling of the above exception, another exception occurred:

Traceback (most recent call last):
  File "/home/tecimler96/APP/venv/lib/python3.8/site-packages/googleapiclient/discovery_cache/file_cache.py", line 37, in <module>
    from oauth2client.locked_file import LockedFile
ModuleNotFoundError: No module named 'oauth2client'

During handling of the above exception, another exception occurred:

Traceback (most recent call last):
  File "/home/tecimler96/APP/venv/lib/python3.8/site-packages/googleapiclient/discovery_cache/__init__.py", line 44, in autodetect
    from . import file_cache
  File "/home/tecimler96/APP/venv/lib/python3.8/site-packages/googleapiclient/discovery_cache/file_cache.py", line 40, in <module>
    raise ImportError(
ImportError: file_cache is unavailable when using oauth2client >= 4.0.0 or google-auth
2020-06-30 08:06:08,598 INFO Refreshing credentials due to a 401 response. Attempt 1/2. @ request from module google_auth_httplib2
2020-06-30 08:06:12,458 ERROR list index out of range...this is very very bad @ save_to_database @ save_to_database from module scraper
2020-06-30 08:06:12,485 WARNING file_cache is unavailable when using oauth2client >= 4.0.0 or google-auth @ autodetect from module __init__
Traceback (most recent call last):
  File "/home/tecimler96/APP/venv/lib/python3.8/site-packages/googleapiclient/discovery_cache/file_cache.py", line 33, in <module>
    from oauth2client.contrib.locked_file import LockedFile
ModuleNotFoundError: No module named 'oauth2client'

During handling of the above exception, another exception occurred:

Traceback (most recent call last):
  File "/home/tecimler96/APP/venv/lib/python3.8/site-packages/googleapiclient/discovery_cache/file_cache.py", line 37, in <module>
    from oauth2client.locked_file import LockedFile
ModuleNotFoundError: No module named 'oauth2client'

During handling of the above exception, another exception occurred:

Traceback (most recent call last):
  File "/home/tecimler96/APP/venv/lib/python3.8/site-packages/googleapiclient/discovery_cache/__init__.py", line 44, in autodetect
    from . import file_cache
  File "/home/tecimler96/APP/venv/lib/python3.8/site-packages/googleapiclient/discovery_cache/file_cache.py", line 40, in <module>
    raise ImportError(
ImportError: file_cache is unavailable when using oauth2client >= 4.0.0 or google-auth
2020-06-30 08:06:12,767 INFO Refreshing credentials due to a 401 response. Attempt 1/2. @ request from module google_auth_httplib2
2020-06-30 08:06:12,940 WARNING Encountered 403 Forbidden with reason "insufficientPermissions" @ _should_retry_response from module http
2020-06-30 08:06:12,942 ERROR <HttpError 403 when requesting https://www.googleapis.com/gmail/v1/users/me/messages/1720a81062ba6754/modify?alt=json returned "Insufficient Permission">  @ do_scrape from module scraper
